FDD Processors Test Report
==================================================

Tests Run: 3
Failures: 0
Errors: 2
Skipped: 0


Errors:
test_document_organizer (__main__.TestFDDProcessors.test_document_organizer): Traceback (most recent call last):
  File "C:\Projects\generative-ai\tests\test_fdd_processors.py", line 70, in test_document_organizer
    doc_id = organizer.process_document(str(self.test_file))
             ^^^^^^^^^^^^^^^^^^^^^^^^^^^^^^^^^^^^^^^^^^^^^^^
  File "C:\Projects\generative-ai\fdd_document_organizer.py", line 112, in process_document
    self._process_sections(doc_data, document_id)
  File "C:\Projects\generative-ai\fdd_document_organizer.py", line 150, in _process_sections
    cursor.execute("""
sqlite3.IntegrityError: UNIQUE constraint failed: sections.document_id, sections.item_number

test_info_extractor (__main__.TestFDDProcessors.test_info_extractor): Traceback (most recent call last):
  File "C:\Projects\generative-ai\tests\test_fdd_processors.py", line 38, in test_info_extractor
    extractor = FDDInfoExtractor(str(self.test_file))
                ^^^^^^^^^^^^^^^^^^^^^^^^^^^^^^^^^^^^^
  File "C:\Projects\generative-ai\fdd_info_extractor.py", line 15, in __init__
    genai.configure(api_key=os.environ["GOOGLE_API_KEY"])
                            ~~~~~~~~~~^^^^^^^^^^^^^^^^^^
  File "<frozen os>", line 679, in __getitem__
KeyError: 'GOOGLE_API_KEY'

